Workbook

Sheet Journal
B2: date | C2: Temps | D2: type de travail | E2: description | G2: type de travail | H2: somme
B3: 22.04.2026 | C3: 0.29166667 | D3: Documentation | E3: Création du cahier des charges | G3: Cours | H3: =SUMIF(Journal[type de travail],types[[#This Row],[type de travail]],Journal[Temps])*24 -> 0 | I3: =types[[#This Row],[somme]]/$H$11 -> 0 | J3: {=_xlfn._xlws.FILTER(G3:G11,H3:H11>0)} -> Plannification | K3: {=_xlfn._xlws.FILTER(H3:H11,H3:H11>0)} -> 2.5
B4: 27.04.2026 | C4: 0.10416667 | D4: Plannification | E4: Création de la plannification global du projet avec les différents sprints | G4: Plannification | H4: =SUMIF(Journal[type de travail],types[[#This Row],[type de travail]],Journal[Temps])*24 -> 2.5 | I4: =types[[#This Row],[somme]]/$H$11 -> 0.046875 | J4: Recherche | K4: 7.5
B5: 30.04.2026 | C5: 0.125 | D5: Documentation | E5: Réedition du cahier des charges | G5: Recherche | H5: =SUMIF(Journal[type de travail],types[[#This Row],[type de travail]],Journal[Temps])*24 -> 7.5 | I5: =types[[#This Row],[somme]]/$H$11 -> 0.140625 | J5: Documentation | K5: 22.333333
B6: 30.04.2026 | C6: 0.083333333 | D6: Documentation | E6: Création du dépot GitHub, arboressance du projet et README | G6: Documentation | H6: =SUMIF(Journal[type de travail],types[[#This Row],[type de travail]],Journal[Temps])*24 -> 22.333333 | I6: =types[[#This Row],[somme]]/$H$11 -> 0.41875 | J6: Tests | K6: 1
B7: 30.04.2026 | C7: 0.083333333 | D7: Recherche | E7: Recherche de protocol de comm. + recherche sur le projet | G7: Programmation | H7: =SUMIF(Journal[type de travail],types[[#This Row],[type de travail]],Journal[Temps])*24 -> 0 | I7: =types[[#This Row],[somme]]/$H$11 -> 0 | J7: Prototypage | K7: 20
B8: 01.05.2026 | C8: 0.125 | D8: Recherche | E8: Recherche de composants | G8: Tests | H8: =SUMIF(Journal[type de travail],types[[#This Row],[type de travail]],Journal[Temps])*24 -> 1 | I8: =types[[#This Row],[somme]]/$H$11 -> 0.01875 | J8: Somme | K8: 53.333333
B9: 01.05.2026 | C9: 0.125 | D9: Documentation | E9: Documentation des composant séléctionnés | G9: Prototypage | H9: =SUMIF(Journal[type de travail],types[[#This Row],[type de travail]],Journal[Temps])*24 -> 20
B10: 01.05.2026 | C10: 0.041666667 | D10: Recherche | E10: Recherche des composant chez distributeur | G10: Présentation | H10: =SUMIF(Journal[type de travail],types[[#This Row],[type de travail]],Journal[Temps])*24 -> 0 | I10: =types[[#This Row],[somme]]/$H$11 -> 0
B11: 01.05.2026 | C11: 0.020833333 | D11: Documentation | E11: Création d'une liste de composant avec prix | G11: Somme | H11: =SUM(H3:H10) -> 53.333333 | I11: =types[[#This Row],[somme]]/$H$11 -> 1
B12: 46146 | C12: 0.083333333 | D12: Prototypage | E12: Ajout des différentes librairies sur KiCad
B13: 46146 | C13: 0.16666667 | D13: Prototypage | E13: Création d'une librairie de composants pour le projet | G13: Temps restant | H13: =SUM(Plannification!C2:S2)-H11 -> 21.666667
B14: 46146 | C14: 0.0625 | D14: Prototypage | E14: Circuit d'alimentation avec schéma + liste de matériel
B15: 46147 | C15: 0.125 | D15: Prototypage | E15: Refonte de l'alimentation + norme EN 55032 Classe B
B16: 46147 | C16: 0.013888889 | D16: Documentation | E16: Ajout de toutes les documentation + prix des composants
B17: 46148 | C17: 0.0625 | D17: Documentation | E17: Documentation technique du schéma du prototype
B18: 46148 | C18: 0.33333333 | D18: Prototypage | E18: Placement des composant, routage sur le PCB du prototype
B19: 46149 | C19: 0.083333333 | D19: Documentation | E19: Documentation de l'implémentation du prototypage
B20: 46149 | C20: 0.0625 | D20: Prototypage | E20: Discution avec JET (ELT2) pour l'impression de la carte
B21: 46149 | C21: 0.041666667 | D21: Tests | E21: Correction de la violation de la RDC.
B22: 46149 | C22: 0.0625 | D22: Recherche | E22: Recherche de solution pour le software
B23: 46149 | C23: 0.10416667 | D23: Documentation | E23: Documentation des différents choix pour le software
B24: 46159 | C24: 0.020833333 | D24: Documentation | E24: Commande mouser

Sheet SommeParJours
A1: date | B1: somme
A2: {=_xlfn.UNIQUE(Journal[date])} -> 22.04.2026 | B2: =SUMIF(Journal[date],SommeParJours!A2,Journal[Temps]) -> 0.29166667
A3: 27.04.2026 | B3: =SUMIF(Journal[date],SommeParJours!A3,Journal[Temps]) -> 0.10416667
A4: 30.04.2026 | B4: =SUMIF(Journal[date],SommeParJours!A4,Journal[Temps]) -> 0.29166667
A5: 01.05.2026 | B5: =SUMIF(Journal[date],SommeParJours!A5,Journal[Temps]) -> 0.3125
A6: 46146 | B6: =SUMIF(Journal[date],SommeParJours!A6,Journal[Temps]) -> 0.3125
A7: 46147 | B7: =SUMIF(Journal[date],SommeParJours!A7,Journal[Temps]) -> 0.13888889
A8: 46148 | B8: =SUMIF(Journal[date],SommeParJours!A8,Journal[Temps]) -> 0.39583333
A9: 46149 | B9: =SUMIF(Journal[date],SommeParJours!A9,Journal[Temps]) -> 0.35416667
A10: 46159 | B10: =SUMIF(Journal[date],SommeParJours!A10,Journal[Temps]) -> 0.020833333
B11: =SUMIF(Journal[date],SommeParJours!A11,Journal[Temps]) -> 0
B12: =SUMIF(Journal[date],SommeParJours!A12,Journal[Temps]) -> 0
B13: =SUMIF(Journal[date],SommeParJours!A13,Journal[Temps]) -> 0
B14: =SUMIF(Journal[date],SommeParJours!A14,Journal[Temps]) -> 0
B15: =SUMIF(Journal[date],SommeParJours!A15,Journal[Temps]) -> 0
B16: =SUMIF(Journal[date],SommeParJours!A16,Journal[Temps]) -> 0
B17: =SUMIF(Journal[date],SommeParJours!A17,Journal[Temps]) -> 0
B18: =SUMIF(Journal[date],SommeParJours!A18,Journal[Temps]) -> 0
B19: =SUMIF(Journal[date],SommeParJours!A19,Journal[Temps]) -> 0
B20: =SUMIF(Journal[date],SommeParJours!A20,Journal[Temps]) -> 0
B21: =SUMIF(Journal[date],SommeParJours!A21,Journal[Temps]) -> 0
B22: =SUMIF(Journal[date],SommeParJours!A22,Journal[Temps]) -> 0
... B25: =SUMIF(Journal[date],SommeParJours!A25,Journal[Temps]) -> 0
B26: =SUMIF(Journal[date],SommeParJours!A26,Journal[Temps]) -> 0 | C26: =SUMIF(Journal[date],SommeParJours!A26,Journal[Temps]) -> 0
B27: =SUMIF(Journal[date],SommeParJours!A27,Journal[Temps]) -> 0 | C27: =SUMIF(Journal[date],SommeParJours!A27,Journal[Temps]) -> 0
C28: =SUMIF(Journal[date],SommeParJours!A28,Journal[Temps]) -> 0
C29: =SUMIF(Journal[date],SommeParJours!A29,Journal[Temps]) -> 0
C30: =SUMIF(Journal[date],SommeParJours!A30,Journal[Temps]) -> 0
C31: =SUMIF(Journal[date],SommeParJours!A31,Journal[Temps]) -> 0
C32: =SUMIF(Journal[date],SommeParJours!A32,Journal[Temps]) -> 0
C33: =SUMIF(Journal[date],SommeParJours!A33,Journal[Temps]) -> 0
C34: =SUMIF(Journal[date],SommeParJours!A34,Journal[Temps]) -> 0
C35: =SUMIF(Journal[date],SommeParJours!A35,Journal[Temps]) -> 0
C36: =SUMIF(Journal[date],SommeParJours!A36,Journal[Temps]) -> 0
C37: =SUMIF(Journal[date],SommeParJours!A37,Journal[Temps]) -> 0
C38: =SUMIF(Journal[date],SommeParJours!A38,Journal[Temps]) -> 0
C39: =SUMIF(Journal[date],SommeParJours!A39,Journal[Temps]) -> 0
B40: =IF(C40>0,C40,"") | C40: =SUMIF(Journal[date],SommeParJours!A40,Journal[Temps]) -> 0
B41: =IF(C41>0,C41,"") | C41: =SUMIF(Journal[date],SommeParJours!A41,Journal[Temps]) -> 0
B42: =IF(C42>0,C42,"") | C42: =SUMIF(Journal[date],SommeParJours!A42,Journal[Temps]) -> 0
...

Sheet Plannification
A1: Phases | B1: Tâche | C1: 22.04.2026 | D1: 27.04.2026 | E1: 30.04.2026 | F1: 06.05.2026 | G1: 07.05.2026 | H1: 11.05.2026 | I1: 18.05.2026 | J1: 22.05.2026 | K1: 28.05.2026 | L1: 01.06.2026 | M1: 03.06.2026 | N1: 08.06.2026 | O1: 11.06.2026 | P1: 12.06.2026 | Q1: 15.06.2026 | R1: 17.06.2026 | S1: 18.06.2026
A2: H | C2: 7 | D2: 4 | E2: 4 | F2: 7 | G2: 5 | H2: 7 | I2: 0 | J2: 0 | K2: 5 | L2: 4 | M2: 7 | N2: 4 | O2: 5 | P2: 0 | Q2: 4 | R2: 7 | S2: 5
A3: S | B3: Sprints | C3: =_xlfn.CONCAT("Conception Matérielle (",SUM(C2:G2),"h)") -> Conception Matérielle (27h) | H3: =_xlfn.CONCAT("Développement Logiciel (",SUM(H2:L2),"h)") -> Développement Logiciel (16h) | N3: =_xlfn.CONCAT("Tests, Validation et Livrables (",SUM(C2:G2),"h)") -> Tests, Validation et Livrables (27h) | V3: =SUM(C2:S2) -> 75
A4: Documentation | B4: Plannification | V4: Absence : | W4: 18.05.26 à 22.05.26 : IFA Formation
B6: Cahier des charges
B8: Plannification
B10: Documentation technique
A12: Conception | B12: Choix des composants
B14: Schéma électronique
B16: Implémentation
B18: Tests fonctionnements prototype
A20: Développement logiciel | B20: Arch. de communication (API et automate)
B22: Arch trammes
B24: Schéma de données (stockage)
B26: Librairie RFID
B28: Dév. logiciel embarqué
A30: Tests, Validation et Livrables | B30: Tests globaux
B32: Debug
B34: Schéma électrique final + PCB
B36: Impression PCB + assemblage
B38: Création boitier
B40: Création présentation
B42: Finalisation des livrables (archive du projet)
A44: Jalons | B44: Présentation
V45: Planifié
B46: Remise du travail complet | V46: Dans les temps
V47: Retard
V54: 46185 | W54: réédition des documents
V55: 17 | W55: présentation
V56: 18 | W56: finaliser projet

Sheet PlanificationExemple
B2: Phases | C2: Tâche | D2: Mois | E2: Octobre | F2: Novembre | J2: Décembre | N2: Janvier | R2: Février
D3: S | E3: 4 | F3: 1 | G3: 2 | H3: 3 | I3: 4 | J3: 1 | K3: 2 | L3: 3 | M3: 4 | N3: 1 | O3: 2 | P3: 3 | Q3: 4 | R3: 1 | S3: 2 | U3: 10 semaines à 5 périodes
B4: Étude des besoins | C4: Organigramme | U4: De octobre 2025 à janvier 2026
C6: Service réseau | U6: Remise : 11.02.2026
U7: Présentation : ?
C8: Nombre de nœuds | U8: Remédiation : ?
C10: Sécurité
B12: Conception Logique | C12: Topologie logique
C14: Plan d'adressage IPv4 et IPv6
C16: Planification du projet
B18: Analyse impl. | C18: Plan physique
C20: Liste de matériels
C22: Mise en place de la sécurité
B24: Simulation | C24: Création du réseau sur packet tracer
C26: Test du réseau
C28: Debug du réseau + checklist
B30: Documentation | C30: Journal de travail
C32: Documentation
C34: Préparation a la présentation | V34: Planifiée
V35: Effective
